2018-05-13 19:18:31,615 ERROR: Exception on /edit_profile [POST] [in /Users/kartikbehl/PycharmProjects/Blog/venv/lib/python3.6/site-packages/flask/app.py:1761]
Traceback (most recent call last):
  File "/Users/kartikbehl/PycharmProjects/Blog/venv/lib/python3.6/site-packages/sqlalchemy/engine/base.py", line 1193, in _execute_context
    context)
  File "/Users/kartikbehl/PycharmProjects/Blog/venv/lib/python3.6/site-packages/sqlalchemy/engine/default.py", line 507, in do_execute
    cursor.execute(statement, parameters)
sqlite3.IntegrityError: UNIQUE constraint failed: User.name

The above exception was the direct cause of the following exception:

Traceback (most recent call last):
  File "/Users/kartikbehl/PycharmProjects/Blog/venv/lib/python3.6/site-packages/flask/app.py", line 2292, in wsgi_app
    response = self.full_dispatch_request()
  File "/Users/kartikbehl/PycharmProjects/Blog/venv/lib/python3.6/site-packages/flask/app.py", line 1815, in full_dispatch_request
    rv = self.handle_user_exception(e)
  File "/Users/kartikbehl/PycharmProjects/Blog/venv/lib/python3.6/site-packages/flask/app.py", line 1718, in handle_user_exception
    reraise(exc_type, exc_value, tb)
  File "/Users/kartikbehl/PycharmProjects/Blog/venv/lib/python3.6/site-packages/flask/_compat.py", line 35, in reraise
    raise value
  File "/Users/kartikbehl/PycharmProjects/Blog/venv/lib/python3.6/site-packages/flask/app.py", line 1813, in full_dispatch_request
    rv = self.dispatch_request()
  File "/Users/kartikbehl/PycharmProjects/Blog/venv/lib/python3.6/site-packages/flask/app.py", line 1799, in dispatch_request
    return self.view_functions[rule.endpoint](**req.view_args)
  File "/Users/kartikbehl/PycharmProjects/Blog/venv/lib/python3.6/site-packages/flask_login/utils.py", line 261, in decorated_view
    return func(*args, **kwargs)
  File "/Users/kartikbehl/PycharmProjects/Blog/app/routes.py", line 84, in edit
    db.session.commit()
  File "/Users/kartikbehl/PycharmProjects/Blog/venv/lib/python3.6/site-packages/sqlalchemy/orm/scoping.py", line 153, in do
    return getattr(self.registry(), name)(*args, **kwargs)
  File "/Users/kartikbehl/PycharmProjects/Blog/venv/lib/python3.6/site-packages/sqlalchemy/orm/session.py", line 943, in commit
    self.transaction.commit()
  File "/Users/kartikbehl/PycharmProjects/Blog/venv/lib/python3.6/site-packages/sqlalchemy/orm/session.py", line 467, in commit
    self._prepare_impl()
  File "/Users/kartikbehl/PycharmProjects/Blog/venv/lib/python3.6/site-packages/sqlalchemy/orm/session.py", line 447, in _prepare_impl
    self.session.flush()
  File "/Users/kartikbehl/PycharmProjects/Blog/venv/lib/python3.6/site-packages/sqlalchemy/orm/session.py", line 2254, in flush
    self._flush(objects)
  File "/Users/kartikbehl/PycharmProjects/Blog/venv/lib/python3.6/site-packages/sqlalchemy/orm/session.py", line 2380, in _flush
    transaction.rollback(_capture_exception=True)
  File "/Users/kartikbehl/PycharmProjects/Blog/venv/lib/python3.6/site-packages/sqlalchemy/util/langhelpers.py", line 66, in __exit__
    compat.reraise(exc_type, exc_value, exc_tb)
  File "/Users/kartikbehl/PycharmProjects/Blog/venv/lib/python3.6/site-packages/sqlalchemy/util/compat.py", line 187, in reraise
    raise value
  File "/Users/kartikbehl/PycharmProjects/Blog/venv/lib/python3.6/site-packages/sqlalchemy/orm/session.py", line 2344, in _flush
    flush_context.execute()
  File "/Users/kartikbehl/PycharmProjects/Blog/venv/lib/python3.6/site-packages/sqlalchemy/orm/unitofwork.py", line 391, in execute
    rec.execute(self)
  File "/Users/kartikbehl/PycharmProjects/Blog/venv/lib/python3.6/site-packages/sqlalchemy/orm/unitofwork.py", line 556, in execute
    uow
  File "/Users/kartikbehl/PycharmProjects/Blog/venv/lib/python3.6/site-packages/sqlalchemy/orm/persistence.py", line 177, in save_obj
    mapper, table, update)
  File "/Users/kartikbehl/PycharmProjects/Blog/venv/lib/python3.6/site-packages/sqlalchemy/orm/persistence.py", line 768, in _emit_update_statements
    execute(statement, multiparams)
  File "/Users/kartikbehl/PycharmProjects/Blog/venv/lib/python3.6/site-packages/sqlalchemy/engine/base.py", line 948, in execute
    return meth(self, multiparams, params)
  File "/Users/kartikbehl/PycharmProjects/Blog/venv/lib/python3.6/site-packages/sqlalchemy/sql/elements.py", line 269, in _execute_on_connection
    return connection._execute_clauseelement(self, multiparams, params)
  File "/Users/kartikbehl/PycharmProjects/Blog/venv/lib/python3.6/site-packages/sqlalchemy/engine/base.py", line 1060, in _execute_clauseelement
    compiled_sql, distilled_params
  File "/Users/kartikbehl/PycharmProjects/Blog/venv/lib/python3.6/site-packages/sqlalchemy/engine/base.py", line 1200, in _execute_context
    context)
  File "/Users/kartikbehl/PycharmProjects/Blog/venv/lib/python3.6/site-packages/sqlalchemy/engine/base.py", line 1413, in _handle_dbapi_exception
    exc_info
  File "/Users/kartikbehl/PycharmProjects/Blog/venv/lib/python3.6/site-packages/sqlalchemy/util/compat.py", line 203, in raise_from_cause
    reraise(type(exception), exception, tb=exc_tb, cause=cause)
  File "/Users/kartikbehl/PycharmProjects/Blog/venv/lib/python3.6/site-packages/sqlalchemy/util/compat.py", line 186, in reraise
    raise value.with_traceback(tb)
  File "/Users/kartikbehl/PycharmProjects/Blog/venv/lib/python3.6/site-packages/sqlalchemy/engine/base.py", line 1193, in _execute_context
    context)
  File "/Users/kartikbehl/PycharmProjects/Blog/venv/lib/python3.6/site-packages/sqlalchemy/engine/default.py", line 507, in do_execute
    cursor.execute(statement, parameters)
sqlalchemy.exc.IntegrityError: (sqlite3.IntegrityError) UNIQUE constraint failed: User.name [SQL: 'UPDATE "User" SET name=? WHERE "User".id = ?'] [parameters: ('susan', 1)] (Background on this error at: http://sqlalche.me/e/gkpj)
2018-05-13 19:18:47,247 INFO: Microblog editProfile [in /Users/kartikbehl/PycharmProjects/Blog/app/routes.py:79]
2018-05-13 19:20:55,436 INFO: Microblog startup [in /Users/kartikbehl/PycharmProjects/Blog/app/__init__.py:46]
2018-05-13 19:20:59,076 INFO: Microblog editProfile [in /Users/kartikbehl/PycharmProjects/Blog/app/routes.py:79]
2018-05-13 19:21:03,454 INFO: Microblog editProfile [in /Users/kartikbehl/PycharmProjects/Blog/app/routes.py:79]
2018-05-13 19:21:07,976 INFO: Microblog editProfile [in /Users/kartikbehl/PycharmProjects/Blog/app/routes.py:79]
2018-05-13 19:21:07,986 INFO: Microblog editProfile [in /Users/kartikbehl/PycharmProjects/Blog/app/routes.py:79]
2018-05-13 19:21:23,421 INFO: Microblog startup [in /Users/kartikbehl/PycharmProjects/Blog/app/__init__.py:46]
2018-05-13 19:21:57,952 INFO: Microblog startup [in /Users/kartikbehl/PycharmProjects/Blog/app/__init__.py:46]
2018-05-13 19:25:58,796 INFO: Microblog startup [in /Users/kartikbehl/PycharmProjects/Blog/app/__init__.py:46]
2018-05-13 19:26:05,617 INFO: Microblog startup [in /Users/kartikbehl/PycharmProjects/Blog/app/__init__.py:46]
2018-05-13 19:27:01,580 INFO: Microblog startup [in /Users/kartikbehl/PycharmProjects/Blog/app/__init__.py:46]
2018-05-13 19:27:54,276 INFO: Microblog startup [in /Users/kartikbehl/PycharmProjects/Blog/app/__init__.py:46]
2018-05-13 19:28:37,415 INFO: Microblog startup [in /Users/kartikbehl/PycharmProjects/Blog/app/__init__.py:46]
2018-05-13 19:35:17,207 INFO: Microblog startup [in /Users/kartikbehl/PycharmProjects/Blog/app/__init__.py:46]
2018-05-13 19:35:20,619 ERROR: Exception on /index [GET] [in /Users/kartikbehl/PycharmProjects/Blog/venv/lib/python3.6/site-packages/flask/app.py:1761]
Traceback (most recent call last):
  File "/Users/kartikbehl/PycharmProjects/Blog/venv/lib/python3.6/site-packages/flask/app.py", line 2292, in wsgi_app
    response = self.full_dispatch_request()
  File "/Users/kartikbehl/PycharmProjects/Blog/venv/lib/python3.6/site-packages/flask/app.py", line 1815, in full_dispatch_request
    rv = self.handle_user_exception(e)
  File "/Users/kartikbehl/PycharmProjects/Blog/venv/lib/python3.6/site-packages/flask/app.py", line 1718, in handle_user_exception
    reraise(exc_type, exc_value, tb)
  File "/Users/kartikbehl/PycharmProjects/Blog/venv/lib/python3.6/site-packages/flask/_compat.py", line 35, in reraise
    raise value
  File "/Users/kartikbehl/PycharmProjects/Blog/venv/lib/python3.6/site-packages/flask/app.py", line 1813, in full_dispatch_request
    rv = self.dispatch_request()
  File "/Users/kartikbehl/PycharmProjects/Blog/venv/lib/python3.6/site-packages/flask/app.py", line 1799, in dispatch_request
    return self.view_functions[rule.endpoint](**req.view_args)
  File "/Users/kartikbehl/PycharmProjects/Blog/venv/lib/python3.6/site-packages/flask_login/utils.py", line 261, in decorated_view
    return func(*args, **kwargs)
  File "/Users/kartikbehl/PycharmProjects/Blog/app/routes.py", line 18, in index
    posts = Post.query.filter_by(not_(Post.user_id.contains(current_user.id))).all()
TypeError: filter_by() takes 1 positional argument but 2 were given
2018-05-13 19:35:49,947 INFO: Microblog startup [in /Users/kartikbehl/PycharmProjects/Blog/app/__init__.py:46]
